[2024-05-20T04:46:03.384+0000] {local_task_job_runner.py:120} INFO - ::group::Pre task execution logs
[2024-05-20T04:46:03.402+0000] {taskinstance.py:2076} INFO - Dependencies all met for dep_context=non-requeueable deps ti=<TaskInstance: dag_ETL.conexion_redshift manual__2024-05-20T04:30:08.190448+00:00 [queued]>
[2024-05-20T04:46:03.408+0000] {taskinstance.py:2076} INFO - Dependencies all met for dep_context=requeueable deps ti=<TaskInstance: dag_ETL.conexion_redshift manual__2024-05-20T04:30:08.190448+00:00 [queued]>
[2024-05-20T04:46:03.408+0000] {taskinstance.py:2306} INFO - Starting attempt 2 of 2
[2024-05-20T04:46:03.418+0000] {taskinstance.py:2330} INFO - Executing <Task(PythonOperator): conexion_redshift> on 2024-05-20 04:30:08.190448+00:00
[2024-05-20T04:46:03.423+0000] {standard_task_runner.py:63} INFO - Started process 283 to run task
[2024-05-20T04:46:03.425+0000] {standard_task_runner.py:90} INFO - Running: ['***', 'tasks', 'run', 'dag_ETL', 'conexion_redshift', 'manual__2024-05-20T04:30:08.190448+00:00', '--job-id', '22', '--raw', '--subdir', 'DAGS_FOLDER/dag.py', '--cfg-path', '/tmp/tmpfrqspzup']
[2024-05-20T04:46:03.426+0000] {standard_task_runner.py:91} INFO - Job 22: Subtask conexion_redshift
[2024-05-20T04:46:03.457+0000] {task_command.py:426} INFO - Running <TaskInstance: dag_ETL.conexion_redshift manual__2024-05-20T04:30:08.190448+00:00 [running]> on host 8251e45c28eb
[2024-05-20T04:46:03.516+0000] {taskinstance.py:2648} INFO - Exporting env vars: AIRFLOW_CTX_DAG_OWNER='***' AIRFLOW_CTX_DAG_ID='dag_ETL' AIRFLOW_CTX_TASK_ID='conexion_redshift' AIRFLOW_CTX_EXECUTION_DATE='2024-05-20T04:30:08.190448+00:00' AIRFLOW_CTX_TRY_NUMBER='2' AIRFLOW_CTX_DAG_RUN_ID='manual__2024-05-20T04:30:08.190448+00:00'
[2024-05-20T04:46:03.517+0000] {taskinstance.py:430} INFO - ::endgroup::
[2024-05-20T04:46:04.149+0000] {taskinstance.py:441} INFO - ::group::Post task execution logs
[2024-05-20T04:46:04.150+0000] {taskinstance.py:2905} ERROR - Task failed with exception
Traceback (most recent call last):
  File "/home/airflow/.local/lib/python3.10/site-packages/airflow/models/taskinstance.py", line 465, in _execute_task
    result = _execute_callable(context=context, **execute_callable_kwargs)
  File "/home/airflow/.local/lib/python3.10/site-packages/airflow/models/taskinstance.py", line 432, in _execute_callable
    return execute_callable(context=context, **execute_callable_kwargs)
  File "/home/airflow/.local/lib/python3.10/site-packages/airflow/models/baseoperator.py", line 400, in wrapper
    return func(self, *args, **kwargs)
  File "/home/airflow/.local/lib/python3.10/site-packages/airflow/operators/python.py", line 235, in execute
    return_value = self.execute_callable()
  File "/home/airflow/.local/lib/python3.10/site-packages/airflow/operators/python.py", line 252, in execute_callable
    return self.python_callable(*self.op_args, **self.op_kwargs)
  File "/opt/airflow/dags/api_connect.py", line 46, in connect_redshift
    conn = psycopg2.connect(
  File "/home/airflow/.local/lib/python3.10/site-packages/psycopg2/__init__.py", line 122, in connect
    conn = _connect(dsn, connection_factory=connection_factory, **kwasync)
psycopg2.OperationalError: connection to server at "data-engineer-cluster.cyhh5bfevlmn.us-east-1.redshift.amazonaws.com" (52.44.43.227), port 5439 failed: fe_sendauth: no password supplied

[2024-05-20T04:46:04.156+0000] {taskinstance.py:1206} INFO - Marking task as FAILED. dag_id=dag_ETL, task_id=conexion_redshift, run_id=manual__2024-05-20T04:30:08.190448+00:00, execution_date=20240520T043008, start_date=20240520T044603, end_date=20240520T044604
[2024-05-20T04:46:04.165+0000] {standard_task_runner.py:110} ERROR - Failed to execute job 22 for task conexion_redshift (connection to server at "data-engineer-cluster.cyhh5bfevlmn.us-east-1.redshift.amazonaws.com" (52.44.43.227), port 5439 failed: fe_sendauth: no password supplied
; 283)
[2024-05-20T04:46:04.199+0000] {local_task_job_runner.py:240} INFO - Task exited with return code 1
[2024-05-20T04:46:04.215+0000] {taskinstance.py:3498} INFO - 0 downstream tasks scheduled from follow-on schedule check
[2024-05-20T04:46:04.218+0000] {local_task_job_runner.py:222} INFO - ::endgroup::
