[2024-05-21T01:56:29.560+0000] {task_context_logger.py:104} ERROR - Executor reports task instance <TaskInstance: dag_ETL.transformar_data manual__2024-05-21T01:56:28.074941+00:00 [queued]> finished (failed) although the task says it's queued. (Info: None) Was the task killed externally?
